Workbook

Sheet BASE
A1: N° Vacante | B1: Fecha de solicitud | C1: Días de apertura | D1: Selector | E1: Estado de aprobación | F1: ¿Aplica para movimiento interno de reasignación? | G1: Confidencial | H1: Vacante sujeta a futura desvinculación | I1: Fecha estimada de desvinculación | J1: Unidad de Negocio | K1: Razon Social | L1: Sector | M1: Centro de Costo | N1: Familia de Puesto | O1: Puesto | P1: Líder | Q1: Hiring Manager | R1: Status general | S1: Status del proceso | T1: Fecha estimada de ingreso | U1: Dificultad | V1: Prioridad | W1: Tipo de vacante | X1: Número de Legajo del reemplazo | Y1: Nombre de reemplazo | Z1: Motivo de contratación | AA1: Modalidad de contratación | AB1: Justificación de la cobertura | AC1: ¿Qué ocurre si la vacante no se cubre? | AD1: Horario | AE1: Lugar de trabajo | AF1: Fecha de cierre | AG1: Fecha de Ingreso | AH1: Tipo de Búsqueda | AI1: Fuente de selección | AJ1: Nombre del seleccionado/a | AK1: Remuneración acordada | AL1: CCT | AM1: Notebook | AN1: Blue | AO1: Comentarios
A2: 00001 | B2: 45673 | C2: =IF(B2="","",IF(OR(TRIM(R2)="En curso",TRIM(R2)="En proceso de ingreso"),TODAY()-B2,"Cerrada")) -> Cerrada | D2: Franco | E2: Aprobada | G2: No | J2: PREPAGA | K2: Cobensil SA | L2: Ventas Retail | M2: Comercial | N2: Comercial, ventas y cobranzas | O2: VENDEDOR/A | P2: Serafin | R2: Cerrada | S2: Ingreso | W2: Reemplazo | Y2: MOYANO ARIANA SOLEDAD (168710) | AA2: Inderminado | AD2: Lunes a Viernes de 10 a 18hs | AE2: Sede Colegiales (Lacroze 3257) | AF2: 46057 | AG2: 46063 | AJ2: BANEGAS NEMBHARD, MARYANA ALEXANDRA | AK2: $1.271.329,36 bruto / $1.036.688,00 neto | AL2: 130/75 | AM2: No | AN2: No
A3: 00002 | B3: 45678 | C3: =IF(B3="","",IF(OR(TRIM(R3)="En curso",TRIM(R3)="En proceso de ingreso"),TODAY()-B3,"Cerrada")) -> Cerrada | D3: Franco | E3: Aprobada | J3: PREPAGA | L3: Ventas Retail | M3: Comercial | N3: Comercial, ventas y cobranzas | O3: VENDEDOR/A | P3: Serafin | R3: Cerrada | S3: Ingreso | W3: Apertura de puesto | AA3: Inderminado | AF3: 46064 | AG3: 46071 | AJ3: Matias Yanez
A4: 00003 | B4: 45678 | C4: =IF(B4="","",IF(OR(TRIM(R4)="En curso",TRIM(R4)="En proceso de ingreso"),TODAY()-B4,"Cerrada")) -> Cerrada | D4: Franco | E4: Aprobada | J4: PREPAGA | L4: Ventas Retail | M4: Comercial | N4: Comercial, ventas y cobranzas | O4: VENDEDOR/A | P4: Serafin | R4: Cerrada | S4: Ingreso | W4: Apertura de puesto | AA4: Inderminado | AF4: 46064 | AG4: 46071 | AJ4: Perla Carvajal
A5: 00004 | B5: 45678 | C5: =IF(B5="","",IF(OR(TRIM(R5)="En curso",TRIM(R5)="En proceso de ingreso"),TODAY()-B5,"Cerrada")) -> Cerrada | D5: Franco | E5: Aprobada | G5: No | J5: PREPAGA | K5: Cobensil SA | L5: Ventas Retail | M5: Comercial | N5: Comercial, ventas y cobranzas | O5: VENDEDOR/A | P5: Serafin | Q5: Sergio Couceiro | R5: Cerrada | S5: Ingreso | T5: 46100 | U5: Baja | V5: Media | W5: Apertura de puesto | AA5: Inderminado | AD5: Lunes a Viernes de 10 a 18 hs | AE5: Cober - Vicente Lopez | AF5: 46094 | AG5: 46100 | AH5: Externa | AI5: Consultora | AJ5: Lady Gomes | AK5: $1.271.329,36 Bruto | AL5: 130/75 | AM5: NO | AN5: No
A6: 00005 | B6: 45678 | C6: =IF(B6="","",IF(OR(TRIM(R6)="En curso",TRIM(R6)="En proceso de ingreso"),TODAY()-B6,"Cerrada")) -> Cerrada | D6: Franco | E6: Aprobada | G6: No | J6: PREPAGA | K6: Cobensil SA | L6: Ventas Retail | M6: Comercial | N6: Comercial, ventas y cobranzas | O6: VENDEDOR/A | P6: Serafin | Q6: Sergio Couceiro | R6: Cerrada | S6: Ingreso | T6: 46100 | U6: Baja | V6: Media | W6: Apertura de puesto | AA6: Inderminado | AD6: Lunes a Viernes de 10 a 18 hs | AE6: Cober - Vicente Lopez | AF6: 46094 | AG6: 46100 | AH6: Externa | AI6: Consultora | AJ6: Joel Dree | AK6: $1.271.329,36 Bruto | AL6: 130/75 | AM6: NO | AN6: No
A7: 00006 | B7: 45678 | C7: =IF(B7="","",IF(OR(TRIM(R7)="En curso",TRIM(R7)="En proceso de ingreso"),TODAY()-B7,"Cerrada")) -> Cerrada | D7: Franco | E7: Aprobada | G7: No | J7: PREPAGA | K7: Cobensil SA | L7: Ventas Retail | M7: Comercial | N7: Comercial, ventas y cobranzas | O7: VENDEDOR/A | P7: Serafin | Q7: Sergio Couceiro | R7: Cerrada | S7: Ingreso | T7: 46100 | U7: Baja | V7: Media | W7: Apertura de puesto | AA7: Inderminado | AD7: Lunes a Viernes de 10 a 18 hs | AE7: Cober - Vicente Lopez | AF7: 46094 | AG7: 46100 | AH7: Externa | AI7: Consultora | AJ7: Romina Rojas | AK7: $1.271.329,36 Bruto | AL7: 130/75 | AM7: NO | AN7: No
A8: 00007 | B8: 45678 | C8: =IF(B8="","",IF(OR(TRIM(R8)="En curso",TRIM(R8)="En proceso de ingreso"),TODAY()-B8,"Cerrada")) -> Cerrada | D8: Franco | E8: Aprobada | G8: No | J8: PREPAGA | K8: Cobensil SA | L8: Ventas Retail | M8: Comercial | N8: Comercial, ventas y cobranzas | O8: VENDEDOR/A | P8: Serafin | Q8: Patricia Mozota | R8: Cerrada | S8: Ingreso | T8: 46100 | U8: Baja | V8: Media | W8: Apertura de puesto | AA8: Inderminado | AD8: Lunes a Viernes de 10 a 18 hs | AE8: Cober - Lacroze | AF8: 46094 | AG8: 46100 | AH8: Externa | AI8: Consultora | AJ8: Carolina Ledesma | AK8: $1.271.329,36 Bruto | AL8: 130/75 | AM8: NO | AN8: No
A9: 00008 | B9: 45678 | C9: =IF(B9="","",IF(OR(TRIM(R9)="En curso",TRIM(R9)="En proceso de ingreso"),TODAY()-B9,"Cerrada")) -> Cerrada | D9: Franco | E9: Aprobada | G9: No | J9: PREPAGA | K9: Cobensil SA | L9: Ventas Retail | M9: Comercial | N9: Comercial, ventas y cobranzas | O9: VENDEDOR/A | P9: Serafin | Q9: Patricia Mozota | R9: Cerrada | S9: Ingreso | T9: 46100 | U9: Baja | W9: Apertura de puesto | AA9: Inderminado | AD9: Lunes a Viernes de 10 a 18 hs | AE9: Cober - Lacroze | AF9: 46094 | AG9: 46100 | AH9: Externa | AI9: Consultora | AJ9: Julieta Gutcovsky | AK9: $1.271.329,36 Bruto | AL9: 130/75 | AM9: NO | AN9: No
A10: 00009 | B10: 45678 | C10: =IF(B10="","",IF(OR(TRIM(R10)="En curso",TRIM(R10)="En proceso de ingreso"),TODAY()-B10,"Cerrada")) -> Cerrada | D10: Franco | E10: Aprobada | G10: No | J10: PREPAGA | K10: Cobensil SA | L10: Ventas Retail | M10: Comercial | N10: Comercial, ventas y cobranzas | O10: VENDEDOR/A | P10: Serafin | Q10: Patricia Mozota | R10: Cerrada | S10: Ingreso | T10: 46100 | U10: Baja | W10: Apertura de puesto | AA10: Inderminado | AD10: Lunes a Viernes de 10 a 18 hs | AE10: Cober - Lacroze | AF10: 46094 | AG10: 46100 | AH10: Externa | AI10: Consultora | AJ10: Noelia Quintana | AK10: $1.271.329,36 Bruto | AL10: 130/75 | AM10: NO | AN10: No
A11: 00010 | B11: 45678 | C11: =IF(B11="","",IF(OR(TRIM(R11)="En curso",TRIM(R11)="En proceso de ingreso"),TODAY()-B11,"Cerrada")) -> Cerrada | D11: Franco | E11: Aprobada | J11: PREPAGA | K11: Bristol Medicine SRL | L11: Ventas Retail | M11: Comercial | N11: Comercial, ventas y cobranzas | O11: VENDEDOR/A | P11: Serafin | Q11: Gabriela Mira | R11: Cerrada | S11: Ingreso | T11: 46100 | U11: Baja | W11: Apertura de puesto | AA11: Inderminado | AD11: Lunes a Viernes de 10 a 17hs | AE11: Bristol - Céspedes | AF11: 46097 | AG11: 46100 | AH11: Externa | AI11: Consultora | AJ11: Ryan Hutchinson | AK11: $961.576,34 Bruto | AL11: 108/75 | AM11: NO | AN11: No
A12: 00011 | B12: 45678 | C12: =IF(B12="","",IF(OR(TRIM(R12)="En curso",TRIM(R12)="En proceso de ingreso"),TODAY()-B12,"Cerrada")) -> Cerrada | D12: Franco | E12: Aprobada | J12: PREPAGA | K12: Bristol Medicine SRL | L12: Ventas Retail | M12: Comercial | N12: Comercial, ventas y cobranzas | O12: VENDEDOR/A | P12: Serafin | Q12: Gabriela Mira | R12: Cerrada | S12: Ingreso | T12: 46100 | U12: Baja | W12: Apertura de puesto | AA12: Inderminado | AD12: Lunes a Viernes de 10 a 17hs | AE12: Bristol - Céspedes | AF12: 46097 | AG12: 46100 | AH12: Externa | AI12: Consultora | AJ12: Katia Lambare | AK12: $961.576,34 Bruto | AL12: 108/75 | AM12: NO | AN12: No
A13: 00012 | B13: 45678 | C13: =IF(B13="","",IF(OR(TRIM(R13)="En curso",TRIM(R13)="En proceso de ingreso"),TODAY()-B13,"Cerrada")) -> Cerrada | D13: Franco | E13: Aprobada | J13: PREPAGA | K13: Bristol Medicine SRL | L13: Ventas Retail | M13: Comercial | N13: Comercial, ventas y cobranzas | O13: VENDEDOR/A | P13: Serafin | Q13: Vanesa Serafin | R13: Cerrada | S13: Ingreso | T13: 46100 | U13: Baja | W13: Apertura de puesto | AA13: Inderminado | AD13: Lunes a Viernes de 10 a 17hs | AE13: Bristol - Céspedes | AF13: 46097 | AG13: 46100 | AH13: Externa | AI13: Consultora | AJ13: Brian Gryncwejg | AK13: $961.576,34 Bruto | AL13: 108/75 | AM13: NO | AN13: No
A14: 00013 | B14: 45818 | C14: =IF(B14="","",IF(OR(TRIM(R14)="En curso",TRIM(R14)="En proceso de ingreso"),TODAY()-B14,"Cerrada")) -> Cerrada | D14: Jose | E14: Aprobada | J14: DROGUERÍA | K14: Reinsal | L14: Ventas | M14: Comercial | N14: Liderazgo | O14: Jefe de Ventas | P14: Serpone | R14: Cerrada | S14: Ingreso | W14: Reemplazo | Y14: Gabriel De Angelis | AA14: Inderminado | AD14: L a V de 9h a 18h | AE14: La Musa | AG14: 46076 | AJ14: Juan Pablo Ratuszniak | AK14: 1800000 Neto | Bruto 2.168.675 | AL14: FUCO | AM14: Ok | AN14: SI | AO14: 14/11 se reclama agenda a Damián por entrevistas, 20/11 Damián conoce 2 candidatos / 25-11 Damian selecciona un candidato. El candidato se baja por mejora salarial en su trabajo. Se baja del proceso. Reinicia la busqueda /Nuestra propuesta 2 millones en mano + comisiones.
A15: 00014 | B15: 45897 | C15: =IF(B15="","",IF(OR(TRIM(R15)="En curso",TRIM(R15)="En proceso de ingreso"),TODAY()-B15,"Cerrada")) -> Cerrada | D15: Jose | E15: Aprobada | J15: PREPAGA | K15: Cobensil | L15: Cobranzas | M15: Facturación y Cobranzas | N15: Liderazgo | O15: Supervisor/a de facturación y cobranzas | P15: Rodríguez | R15: Cerrada | S15: Ingreso | W15: Apertura de puesto | AA15: Inderminado | AD15: L a V de 09h a 18h | AE15: Ravignani | AF15: 46007 | AG15: 46024 | AJ15: Paula García | AK15: 1.800.000$ netos | AL15: FUCO | AO15: 25/11/2025 se presenta una terna de 3 candidatos a Florencia Rodriguez, 05/12 conoció a Paula Garcia, 09/12 fue derivada a psico y preo
A16: 00015 | B16: 45916 | C16: =IF(B16="","",IF(OR(TRIM(R16)="En curso",TRIM(R16)="En proceso de ingreso"),TODAY()-B16,"Cerrada")) -> Cerrada | D16: Jose | E16: Cancelada | J16: Centros Ambulatorios | L16: Mantenimiento | M16: Servicios de Apoyo | N16: Liderazgo | O16: Jefe/a de Mantenimiento | P16: Porretti | R16: Cancelada | S16: Cancelada | U16: Alta | V16: Baja | W16: Apertura de puesto | AA16: Inderminado | AD16: Lunes a Viernes 9 a 18 hs | AK16: $ 3.253.012,05 bruto / $ 2.700.000 neto | AL16: FUCO | AO16: Nicolas Ruiz no apto Labo / 1 candidato en curso OK - banda 3 k brutos . Se presentará dos candidatos que no tienen formación requerida para contemplarlos en el análisis
A17: 00016 | B17: 45931 | C17: =IF(B17="","",IF(OR(TRIM(R17)="En curso",TRIM(R17)="En proceso de ingreso"),TODAY()-B17,"Cerrada")) -> Cerrada | D17: Ema | E17: Aprobada | J17: SANATORIO COLEGIALES | K17: CIRENDSA | L17: Traumatología | M17: Guardia | N17: Asistencial/Médicos | O17: MEDICO/A | P17: Faiman | R17: Cerrada | S17: Ingreso | W17: Reemplazo | AA17: Plazo Fijo | AD17: MARTES 8 A 20 HS | AE17: SANATORIO | AF17: 45974 | AG17: 46028 | AJ17: SAMMY OSPINA | AK17: $977.367,60 bruto / $796.554,59 neto | AL17: AMAP | AM17: NO | AO17: M8-20 - Esperando certificado especialista // 18-12 recibe el certificado de especialdiad // 22-12 contacto con Faiman para definir ingreso // 26-12 confirma su ingreso
A18: 00017 | B18: 45943 | C18: =IF(B18="","",IF(OR(TRIM(R18)="En curso",TRIM(R18)="En proceso de ingreso"),TODAY()-B18,"Cerrada")) -> Cerrada | D18: Jose | E18: Aprobada | J18: SANATORIO COLEGIALES | L18: Comercial | M18: Administración y Finanzas | N18: Liderazgo | O18: Responsable de Ventas Institucionales | P18: Poeta | R18: Cerrada | S18: Ingreso | W18: Reemplazo | Y18: Leandro Gómez | AA18: Inderminado | AG18: 46027 | AJ18: FLorencia Fernandez ( Promoción) | AO18: 19/11 psicotecnico Florencia Fernández actual solaboradora del área / Buscar reemplazo: se presenta 25/11
A19: 00018 | B19: 45945 | C19: =IF(B19="","",IF(OR(TRIM(R19)="En curso",TRIM(R19)="En proceso de ingreso"),TODAY()-B19,"Cerrada")) -> Cerrada | D19: Franco | E19: Aprobada | J19: SANATORIO COLEGIALES | K19: Cirenda | L19: Procesos Retributivos | M19: Administración y Finanzas | N19: Administrativo/a | O19: FACTURISTA | P19: Alvarez | R19: Cerrada | S19: Ingreso | W19: Reemplazo | AA19: Eventual | AD19: Lunes a Viernes de 9 a 18hs | AE19: Sanatorio | AF19: 46027 | AG19: 46034 | AJ19: Anabella Belen Pantano | AK19: $1.207.568,30 Bruto / $1.008.912,50 neto | AL19: 122 | AM19: No | AN19: No | AO19: Débitos
A20: 00019 | B20: 45957 | C20: =IF(B20="","",IF(OR(TRIM(R20)="En curso",TRIM(R20)="En proceso de ingreso"),TODAY()-B20,"Cerrada")) -> Cerrada | D20: Franco | E20: Aprobada | J20: CORPO | K20: Desarollos en salud | L20: Comercial | M20: Administración y Finanzas | N20: Administrativo/a | O20: Administrativo/a comercial | P20: Poeta | R20: Cerrada | S20: Ingreso | W20: Reemplazo | Y20: Florencia Anahi Fernandez (157891) | AA20: Plazo Fijo | AD20: Lunes a Viernes de 9 a 18hs | AE20: La Musa y Sanatorio | AF20: 46021 | AG20: 46034 | AJ20: Yamila Genaisir | AK20: $1.584.578,31 bruto / $1.315.200,00 Neto | AL20: FUCO | AM20: Si | AN20: NO | AO20: Puesto: Administrativa de presupuestos. Reemplaza a Florencia por ascenso de esta misma.
A21: 00020 | B21: 45957 | C21: =IF(B21="","",IF(OR(TRIM(R21)="En curso",TRIM(R21)="En proceso de ingreso"),TODAY()-B21,"Cerrada")) -> Cerrada | D21: Franco | E21: Aprobada | J21: CMV | K21: CMV | L21: Administración y Finanzas | M21: Administración y Finanzas | N21: Administrativo/a | O21: Administrativo/a Contable | P21: Rea | R21: Cerrada | S21: Ingreso | W21: Reemplazo | Y21: Agudelo | AA21: Inderminado | AD21: Lunes a Viernes de 9 a 18hs | AE21: CMV | AF21: 46049 | AG21: 46056 | AJ21: Melanie Laffon | AK21: $1.300.000 neto | AL21: FUCO | AM21: NO | AN21: NO | AO21: 20/11 - Eugenia conoce un candidato, el candidato cancela entrevista, 27/11 - Eugenia en conjunto con Rrhh conocera a 2 candidatos. 2 candidatas en preoc. Iba a ingresar el dia 6/1/25 una candidata pero no se presento. Ese mismo dia se retoma busqueda de perfiles. Se avanza con Melanie Laffon
A22: 00021 | B22: 45962 | C22: =IF(B22="","",IF(OR(TRIM(R22)="En curso",TRIM(R22)="En proceso de ingreso"),TODAY()-B22,"Cerrada")) -> Cerrada | D22: Ema | E22: Aprobada | J22: SANATORIO COLEGIALES | K22: CIRENDSA | L22: Hotelería | M22: Internación | N22: Servicios Generales | O22: MUCAMO/A | P22: Valeria Dodero | R22: Cerrada | S22: Ingreso | W22: Reemplazo | Y22: Libramento T | AA22: Eventual | AD22: 14-22 HS | AE22: SANATORIO | AF22: 46021 | AG22: 46028 | AJ22: LEONOR ORELLANA | AK22: $1.000.154,62 bruto / $830.004,50 NETO | AL22: 122/75 | AM22: no | AO22: 18-12 8 perfiles en preoc / 30-12 apto
A23: 00022 | B23: 45962 | C23: =IF(B23="","",IF(OR(TRIM(R23)="En curso",TRIM(R23)="En proceso de ingreso"),TODAY()-B23,"Cerrada")) -> Cerrada | D23: Ema | E23: Aprobada | J23: SANATORIO COLEGIALES | K23: CIRENDSA | L23: Kinesiología | M23: Terapia Intensiva | N23: Asistencial/Otros | O23: KINESIOLOGO/A | P23: Laredo | R23: Cerrada | S23: Ingreso | W23: Reemplazo | Y23: Menchon J | AA23: Plazo Fijo | AD23: Lunes a Viernes 14 a 20 hs, 1 Sábado y Domingo al mes 8 a 20 hs. Feriado rotativo | AE23: SANATORIO | AF23: 46015 | AG23: 46028 | AJ23: ARACELI SARMIENTO | AK23: $1.962.564,65 bruto / $1.628.956,00 neto | AL23: 122/75 | AM23: NO | AO23: 12/11 Marcos T. - 13/11 18/11 Cvs no avanzan - 28/11 entrevista Lucas M decide no avanzar - 4/12 Patricio M no asiste // 12-12 entrevista Araceli / 18-12 Araceli en preo
A24: 00023 | B24: 45962 | C24: =IF(B24="","",IF(OR(TRIM(R24)="En curso",TRIM(R24)="En proceso de ingreso"),TODAY()-B24,"Cerrada")) -> Cerrada | D24: Ema | E24: Aprobada | J24: SANATORIO COLEGIALES | K24: CIRENDSA | L24: Enfermeria | M24: Terapia Intensiva | N24: Asistencial/Enfermería | O24: Enfermero/a de Terapia Intensiva | P24: Alvez | R24: Cerrada | S24: Ingreso | W24: Reemplazo | Y24: Camino C | AA24: Eventual | AD24: 22 A 6 HS | AE24: SANATORIO | AF24: 46049 | AG24: 46055 | AJ24: STEPHANIE VERA | AK24: $1.554.520,85 bruto / $1.295.707,00 neto | AL24: 122/75 | AM24: NO | AO24: 11/11 entrevista. Perfiles sólo de CM. 20/11 entrevista. No gustaron los perfiles UTI/UCO - 03/12 entrevista. Ninguno con experiencia en UTI/UCO asistió. Agendando nueva entrevista / 6 candidatos en preocupacional
A25: 00024 | B25: 45962 | C25: =IF(B25="","",IF(OR(TRIM(R25)="En curso",TRIM(R25)="En proceso de ingreso"),TODAY()-B25,"Cerrada")) -> Cerrada | D25: Ema | E25: Aprobada | J25: SANATORIO COLEGIALES | K25: CIRENDSA | L25: Enfermeria | M25: Terapia Intensiva | N25: Asistencial/Enfermería | O25: Enfermero/a de Terapia Intensiva | P25: Alvez | R25: Cerrada | S25: Ingreso | W25: Reemplazo | Y25: Ibarra Gilda | AA25: Eventual | AD25: 22 A 6 HS | AE25: SANATORIO | AF25: 46049 | AG25: 46055 | AJ25: MARIA GONZALEZ | AK25: $1.554.520,85 bruto / $1.295.707,00 neto | AL25: 122/75 | AM25: NO | AO25: 11/11 entrevista. Perfiles sólo de CM. 20/11 entrevista. No gustaron los perfiles UTI/UCO - 03/12 entrevista. Ninguno con experiencia en UTI/UCO asistió. Agendando nueva entrevista / 6 candidatos en preocupacional
A26: 00025 | B26: 45962 | C26: =IF(B26="","",IF(OR(TRIM(R26)="En curso",TRIM(R26)="En proceso de ingreso"),TODAY()-B26,"Cerrada")) -> Cerrada | D26: Fer | E26: Aprobada | J26: CORPO | K26: Cober | L26: Gestión de las Personas | M26: Administración y Finanzas | N26: Analista | O26: Liquidador/a de sueldos | P26: Ezequiel | R26: Cerrada | S26: Ingreso | W26: Apertura de puesto | AA26: Inderminado | AD26: Lunes a viernes de 8 a 17hs | AE26: La Musa | AF26: 46027 | AG26: 46034 | AJ26: Eduardo Rodriguez Rosales | AK26: $2.000.000 neto | AL26: FUCO | AM26: Si | AN26: no | AO26: se conoció 1 candidato la primera semana de noviembre, se ajusta el perfil no jr, se sube la remuneración 1.7, se entrevistaron 3 candidatos/ se vuelve a ajusto el perfil diversidad de convios que venga de consultoras. Se derivo a consultora se ajusta salario a 2 M
A27: 00026 | B27: 45972 | C27: =IF(B27="","",IF(OR(TRIM(R27)="En curso",TRIM(R27)="En proceso de ingreso"),TODAY()-B27,"Cerrada")) -> Cerrada | D27: Jose | E27: Aprobada | J27: LABBO | K27: Argil | L27: Laboratorio | M27: Operaciones | N27: Asistencial/Otros | O27: BIOQUIMICO/A | P27: Mercedes | R27: Cerrada | S27: Ingreso | W27: Reemplazo | Y27: Mercdes Miglianone | AA27: Plazo Fijo | AD27: L a V 12h a 18h, Sábado fléxibles | AE27: Argil | AF27: 46017 | AG27: 46040 | AJ27: Valeria Cánovas | AK27: 2.300.000$ Netos | AL27: FUCO | AO27: 25/11 entrevistas, 12/12 Avanza a psico y preo Valeria Cánovas
A28: 00027 | B28: 45973 | C28: =IF(B28="","",IF(OR(TRIM(R28)="En curso",TRIM(R28)="En proceso de ingreso"),TODAY()-B28,"Cerrada")) -> Cerrada | D28: Franco | E28: Aprobada | J28: CORPO | L28: Comunicación | M28: Marketing | N28: Analista | O28: Analista de marketing | P28: Pachelo | R28: Cerrada | S28: Ingreso | W28: Reemplazo | Y28: Camila Osa | AA28: Inderminado | AD28: Lunes a viernes de 9 a 18hs | AE28: Cramer | AF28: 46063 | AG28: 46076 | AJ28: Candela Fernandez | AK28: $1.600.000 neto | AL28: FUCO | AM28: Si. (Pedido lunes 09/02/26) | AN28: NO | AO28: 18/11 - se envía 6 perfiles a Pachelo, se acuerda esperar el retorno de Lucía de vacaciones para avanzar con entrevista grupal, 4/12 entrevista con 3 candidatos - mencionan que les enviemos mas perfiles para tomar una decision, 9/12 se envian por mail 4 cv's para su analisis y poder coordinar entrevistas. 22/12 Se envia feedback a F.Pachelo de las entrevistas de 3 candidatos que nos gustaron luego de realizar entrevistas. / Pachelo selecciona a una candidata + Tenemos 1 backup. Se avanza con Guadalupe Diaz Bo el 23-01-26, 28-01-26 se recibe preoc no apto. En paralelo, se envia a entrevista con F.Pachelo candidata de back up el dia 29-01-26. Se avanza con la candidata de back up Candela Fernandez a preoc.
A29: 00028 | B29: 45975 | C29: =IF(B29="","",IF(OR(TRIM(R29)="En curso",TRIM(R29)="En proceso de ingreso"),TODAY()-B29,"Cerrada")) -> Cerrada | D29: Ema | E29: Aprobada | J29: CMV | K29: CMV | L29: Administración | M29: Administración | N29: Especialista | O29: CONTADOR/A | P29: Colalillo | R29: Cerrada | S29: Ingreso | W29: Reemplazo | Y29: Eugenia Rea | Z29: Desvinculación empresa | AA29: Inderminado | AD29: Lunes a viernes de 9 a 18hs | AE29: LA MUSA | AF29: 46080 | AG29: 46084 | AJ29: JESICA SEGOVIA | AK29: $ 3.132.530,12 bruto / $ 2.600.000 neto | AL29: FUCO | AM29: Si. (Pedido Viernes 27/2) | AN29: NO | AO29: 14/11 relevamiento perfil claudia / 25/11 lectura de cvs / 4/12 3 entrevistas RRHH / 05/12 perfiles enviados a Claudio / 12/12 Claudio solicita entrevistar - 15 a 19/12 Claudio vacaciones / Claudio entrvistatará 2 candidatos ,semana del 26/01 - 02/02 preo y psico / 18/02 - No se generó la vacante
A30: 00029 | B30: 45975 | C30: =IF(B30="","",IF(OR(TRIM(R30)="En curso",TRIM(R30)="En proceso de ingreso"),TODAY()-B30,"Cerrada")) -> Cerrada | D30: Franco | E30: Aprobada | J30: SANATORIO COLEGIALES | K30: Desarollos en salud | L30: Sistemas | M30: Sistemas | N30: Pasante/Becario | O30: Pasante | P30: Gatica | R30: Cerrada | S30: Ingreso | W30: Apertura de puesto | AA30: Inderminado | AD30: 20hs semanales, con horario a coordinar | AE30: SANATORIO | AF30: 46027 | AG30: 46041 | AJ30: Vicente D’Annunzio | AK30: $388.330,00 bruto | AM30: NO | AN30: NO
A31: 00030 | B31: 45975 | C31: =IF(B31="","",IF(OR(TRIM(R31)="En curso",TRIM(R31)="En proceso de ingreso"),TODAY()-B31,"Cerrada")) -> Cerrada | D31: Franco | E31: Aprobada | J31: SANATORIO COLEGIALES | L31: Sistemas | M31: Servicios de Apoyo | N31: Pasante/Becario | O31: Pasante | P31: Gatica | R31: Cerrada | S31: Ingreso | W31: Apertura de puesto | AA31: Inderminado | AF31: 46027 | AG31: 46041 | AJ31: VICENTE D´ANUNZIO | AO31: 4/12 se entrevistan 2 candidatos pero el referente solicita conocer mas candidatos para tomar una decision, 16/12 se conoce un candidato, 18/12 se conoce otro candidato. 22/12 se envia a preoc un candidato
A32: 00031 | B32: 45980 | C32: =IF(B32="","",IF(OR(TRIM(R32)="En curso",TRIM(R32)="En proceso de ingreso"),TODAY()-B32,"Cerrada")) -> Cerrada | D32: Ema | E32: Aprobada | J32: SANATORIO COLEGIALES | K32: CIRENDSA | L32: Admisión | M32: Consultorios Externos | N32: Administrativo/a | O32: ADMISIONISTA | P32: Gomez | R32: Cerrada | S32: Ingreso | W32: Apertura de puesto | Y32: 5° admin PB Laboratorio | AA32: Plazo Fijo | AD32: Lunes a Viernes 8 a 16 hs. Sabado por medio 7 a 15 hs | AE32: SANATORIO | AF32: 46037 | AG32: 46045 | AJ32: VALENTINA RAMIREZ | AK32: $1.164.203,77 bruto / $976.802,50 neto | AL32: 122/75 | AM32: NO | AO32: 05-12 Perfil entrevista ok 08-12 se baja del proceso. 11-12 entrevista. Sin exp real en labo. 17-12 1 perfil ok pero vive en Tigre. Evaluando otras opciones
A33: 00032 | B33: 45985 | C33: =IF(B33="","",IF(OR(TRIM(R33)="En curso",TRIM(R33)="En proceso de ingreso"),TODAY()-B33,"Cerrada")) -> Cerrada | D33: Franco | E33: Aprobada | J33: SANATORIO COLEGIALES | K33: CIRENDSA | L33: Operaciones | M33: Servicios de Apoyo | N33: Servicios Generales | O33: PEON | P33: Cordoba | R33: Cerrada | S33: Ingreso | W33: Reemplazo | Y33: Vacaciones | AA33: Eventual | AD33: ROTATIVO entre 6-14 hs/14-22 hs/22-6 hs segun cronograma | AE33: SANATORIO | AF33: 46024 | AG33: 46034 | AJ33: MAXIMILIANO GUTIERREZ NICOLAS MEDINA LIHUEL RODRIGUEZ | AK33: $1.000.254,62 bruto / $830.085,50 neto | AL33: 122/75 | AM33: NO | AO33: 12/12 6 perfiles citados, asisten 4 y 2 pasan a preo 17/12 asiste uno solo - Entrevista 22/12 // 1 PERFIL APTO 30-12
A34: 00033 | B34: 45986 | C34: =IF(B34="","",IF(OR(TRIM(R34)="En curso",TRIM(R34)="En proceso de ingreso"),TODAY()-B34,"Cerrada")) -> Cerrada | D34: Jose | E34: Aprobada | J34: CORPO | K34: Healthnes | L34: Gestión del Cambio | M34: Administración | N34: Analista | O34: Analista de Procesos | P34: Rodríguez M | R34: Cerrada | S34: Ingreso | W34: Apertura de puesto | AA34: Inderminado | AD34: L a V 09h a 18h | AE34: Cramer | AF34: 46035 | AG34: 46041 | AJ34: Romina Cecchin | AK34: 2.500.000 $ NETOS | AL34: FUCO | AO34: jueves 11/12 María se reune con Emilio para definir quien avanza, 18/12 Hace psico Romina | 12/01 - 1 candidata en preocupacional, fecha de ingreso (probable) - semana 18/01
A35: 00034 | B35: 45986 | C35: =IF(B35="","",IF(OR(TRIM(R35)="En curso",TRIM(R35)="En proceso de ingreso"),TODAY()-B35,"Cerrada")) -> Cerrada | D35: Ema | E35: Aprobada | J35: FARMACIA | K35: NOBEL | L35: Administración y Finanzas | M35: Farmacia Lamaité | N35: Liderazgo | O35: Supervisor/a de Farmacia | P35: Emilio | R35: Cerrada | S35: Ingreso | W35: Reemplazo | Y35: Iván Lara | AA35: Inderminado | AD35: 48 hs semanales de Lunes a Sabado | AE35: LAMAITE | AF35: 46035 | AG35: 46041 | AJ35: SERGIO BERNIGAUD | AK35: $2.000.000 neto | AL35: FUCO | AM35: SI | AO35: 4/12 Entrevista - 5/12 entrevista - 13/12 entrevista Cecilia - 16/12 2 entrevistas - 18/12 entrevista Sergio + 1 perfil consultora conocido 19/12 - 23/12 entrevista Sergio
A36: 00035 | B36: 45986 | C36: =IF(B36="","",IF(OR(TRIM(R36)="En curso",TRIM(R36)="En proceso de ingreso"),TODAY()-B36,"Cerrada")) -> Cerrada | D36: Fer | E36: Aprobada | J36: CORPO | K36: Healtnes | L36: Contact Center | M36: Servicios de Apoyo | N36: Liderazgo | O36: Coordinador/a de Contac Center | P36: Nahir | R36: Cerrada | S36: Ingreso | W36: Reemplazo | Y36: Agostina Zowkoski | AA36: Inderminado | AD36: Lunes a Viernes de 8 a 5hs | AE36: Maure | AF36: 46028 | AG36: 46041 | AJ36: Agustina Campos | AK36: $2200000 neto | AL36: FUCO | AM36: Si | AN36: No | AO36: Se envió 12-12 2 perfiles para entrevista técnica, se entrevisto 17-12 Agustina Campos, pasa a psico el 19-12, se suien evalaundo candidatos
A37: 00036 | B37: 45987 | C37: =IF(B37="","",IF(OR(TRIM(R37)="En curso",TRIM(R37)="En proceso de ingreso"),TODAY()-B37,"Cerrada")) -> Cerrada | D37: Ema | E37: Aprobada | J37: SANATORIO COLEGIALES | L37: Enfermeria | M37: Internación | N37: Asistencial/Enfermería | O37: Enfermero/a de Quimio | P37: Alvez | R37: Cerrada | S37: Ingreso | W37: Reemplazo | Y37: Mazars | AA37: Inderminado | AG37: 46076 | AJ37: YAEL | AO37: L-V 12 a 18h / Pase interno de Piñeiro Y.
A38: 00037 | B38: 45991 | C38: =IF(B38="","",IF(OR(TRIM(R38)="En curso",TRIM(R38)="En proceso de ingreso"),TODAY()-B38,"Cerrada")) -> Cerrada | D38: Ema | E38: Aprobada | J38: SANATORIO COLEGIALES | K38: CIRENDSA | L38: Cirugía | M38: Quirófano | N38: Asistencial/Otros | O38: INSTRUMENTADOR/A | P38: Di Franco | R38: Cerrada | S38: Ingreso | W38: Reemplazo | Y38: Otero R | AA38: Plazo Fijo | AD38: Lunes a Sabados 14 a 22 hs. Feriado rotativo | AE38: SANATORIO | AF38: 46027 | AG38: 46041 | AJ38: AYELEN CARRUBBA | AK38: $1.478.071,38 bruto / $1.230.851,50 neto | AL38: 122/75 | AM38: NO | AO38: 18-12 entrevistas 19-12 Entrevista Ale. Agendando preocupacional 23-12
A39: 00038 | B39: 45994 | C39: =IF(B39="","",IF(OR(TRIM(R39)="En curso",TRIM(R39)="En proceso de ingreso"),TODAY()-B39,"Cerrada")) -> Cerrada | D39: Fer | E39: Aprobada | J39: CORPO | K39: Cober | L39: Gestión de las Personas | M39: Administración y Finanzas | N39: Liderazgo | O39: Coordinador/a de atracción de talento | P39: Daniela | R39: Cerrada | S39: Ingreso | W39: Reemplazo | Y39: Alejandro Alzate | AA39: Inderminado | AD39: Lunes a viernes de 8 a 17hs | AE39: La musa | AF39: 46020 | AG39: 46027 | AJ39: Juan Pablo Sanchez | AK39: 2800000 bruto | AL39: FUCO | AM39: Si
A40: 00039 | B40: 45994 | C40: =IF(B40="","",IF(OR(TRIM(R40)="En curso",TRIM(R40)="En proceso de ingreso"),TODAY()-B40,"Cerrada")) -> Cerrada | D40: Franco | E40: Aprobada | J40: PREPAGA | K40: Cobensil | L40: Cobranzas | M40: Administración y Finanzas | N40: Comercial, ventas y cobranzas | O40: Cobrador/a | P40: Florencia Rodriguez | R40: Cerrada | S40: Ingreso | W40: Reemplazo | Y40: Milenka Barsallo | AA40: Inderminado | AD40: Lunes a Viernes de 11 a 20hs. (Full time) | AE40: Ravignani | AF40: 46020 | AG40: 46028 | AJ40: Romina Llanos | AK40: $1.264.540,33 bruto / $1.033.022,00 neto | AL40: 130/75 | AM40: No | AN40: NO | AO40: 12/12 - Se conocen 3 candidatos, se avanzan con los 3 a preoc.
...

Sheet TD
A1: Unidad de Negocio | B1: (Varios elementos)
A2: Status del proceso | B2: (Todas)
A3: Status general | B3: (Varios elementos)
A5: Cuenta de Familia de Puesto
A6: 73
A10: Status general | B10: (Varios elementos)
A12: Cuenta de Familia de Puesto | B12: Status del proceso
A13: Unidad de Negocio | B13: Relevamiento de Perfil | C13: Publicación/Analizando CVs | D13: Entrevista Atracción de Talento | E13: Preocupacional | F13: Preselección/Screening | G13: Carta Oferta | H13: Entrevista Hiring Manager | I13: Assessment Center | J13: Total general
A14: SANATORIO COLEGIALES | B14: 3 | D14: 6 | E14: 7 | F14: 3 | G14: 9 | I14: 7 | J14: 35
A15: PREPAGA | D15: 3 | E15: 12 | F15: 6 | H15: 1 | J15: 22
A16: CORPO | D16: 2 | E16: 1 | H16: 5 | J16: 8
A17: CMV | C17: 1 | D17: 3 | I17: 2 | J17: 6
A18: FARMACIA | B18: 1 | F18: 1 | J18: 2
A19: Total general | B19: 4 | C19: 1 | D19: 14 | E19: 20 | F19: 10 | G19: 9 | H19: 6 | I19: 9 | J19: 73
A23: Status del proceso | B23: (Varios elementos)
A24: Status general | B24: (Varios elementos)
A26: Unidad de Negocio | B26: Cuenta de Familia de Puesto
A27: SANATORIO COLEGIALES | B27: 28
A28: PREPAGA | B28: 22
A29: CORPO | B29: 8
A30: CMV | B30: 4
A31: FARMACIA | B31: 2
A32: Total general | B32: 64
A37: Status del proceso | B37: (Todas)
A39: Cuenta de Familia de Puesto | B39: Status general
A40: Selector | B40: En curso | C40: En proceso de Ingreso | D40: Total general
A41: Ema | B41: 22 | C41: 13 | D41: 35
A42: Franco | B42: 13 | C42: 13 | D42: 26
A43: Jose | B43: 7 | C43: 4 | D43: 11
A44: Juanpi | B44: 7 | C44: 1 | D44: 8
A45: Total general | B45: 49 | C45: 31 | D45: 80
A48: Status del proceso | B48: (Todas)
A49: Unidad de Negocio | B49: (Todas)
A51: Cuenta de Familia de Puesto | B51: Status general
A52: Familia de Puesto | B52: En curso | C52: En proceso de Ingreso | D52: Total general
A53: Comercial, ventas y cobranzas | B53: 8 | C53: 12 | D53: 20
A54: Asistencial/Enfermería | B54: 13 | C54: 6 | D54: 19
A55: Liderazgo | B55: 7 | C55: 1 | D55: 8
A56: Servicios Generales | B56: 4 | C56: 4 | D56: 8
A57: Asistencial/Otros | B57: 4 | C57: 4 | D57: 8
...

Sheet Referencias
A1: Selector | B1: Unidad | C1: Razon Social | D1: Sector | E1: CECO | F1: Familia de Puestos | G1: Puesto | H1: Status del Proceso | I1: Dificultad | J1: Prioridad | K1: Tipo de Vacante | L1: Motivo de contración | M1: Modalidad de contración | N1: Lugar de trabajo | O1: Fuente de selección | P1: Status General | Q1: Estado de Aprobación
A2: Franco | B2: SANATORIO COLEGIALES | C2: Desarrollos en Salud SA | D2: Enfermeria | E2: INTERNACION | F2: Asistencial/Enfermería | G2: ADMINISTRATIVO/A | H2: Relevamiento de Perfil | I2: Alta | J2: Alta | K2: Apertura de puesto | L2: Desvinculación empresa | M2: Indeterminado | O2: Linkedln | P2: En curso | Q2: Pendiente
A3: Ema | B3: CMD | C3: Cirugía Endovascular SA | D3: HOTELERIA | E3: BELGRANO | F3: Asistencial/Médicos | G3: ENFERMERO/A | H3: Publicación/Analizando CVs | I3: Media | J3: Baja | K3: Reemplazo | L3: Renuncia | M3: Plazo Fijo | O3: Computrabajo | P3: En proceso de Ingreso | Q3: Aprobación Informal
A4: Jose | B4: PREPAGA | C4: Diag por imag de alta complejidad DR Deragopyan SA | D4: ADMISION | E4: ADMINISTRACION Y FINANZAS | F4: Asistencial/Otros | G4: TECNICO/A | H4: Preselección/Screening | I4: Baja | J4: Media | L4: Crecimiento del área | M4: Eventual | O4: Referidos | P4: Cerrada | Q4: Aprobada
A5: Fer | B5: CORPO | C5: Cobensil SA | D5: CLINICA MEDICA | E5: SERVICIOS DE APOYO | F5: Analista | G5: MEDICO/A | H5: Assessment Center | I5: N/A | J5: N/A | L5: Jubilación | O5: Base general | P5: StandBy | Q5: Rechazada
A6: Juanpi | B6: CMV | C6: Healthnes SA | D6: CONTACT CENTER | E6: TERAPIA INTENSIVA | F6: Administrativo/a | G6: MUCAMO/A | H6: Entrevista Atracción de Talento | L6: Nuevo proyecto | O6: Búsqueda Interna | P6: Cancelada | Q6: Cancelada
A7: Dani | B7: DROGUERÍA | C7: Diagnostico por imágenes Pilar SA | D7: CIRUGIA | E7: Operaciones | F7: Especialista | G7: VENDEDOR/A | H7: Entrevista Hiring Manager | L7: Reorganización del área | O7: Promoción | P7: Pendiente de Aprobación
B8: ARGIL | C8: Bristol Medicine SRL | D8: Ventas Retail | E8: Comercial | F8: Servicios Generales | G8: Operador/a | H8: Preocupacional | L8: Movimiento interno | O8: Consultora
B9: FARMACIA | C9: Centrol Médico Vilella SA | D9: MKT CCENTER | E9: PILAR | F9: Mantenimiento y obras | G9: ADMIN.OPER.DE CALL CENTE | H9: Psicotécnico | L9: Licencia
B10: LABBO | C10: Reinsal SA | D10: Cobranzas | E10: Quirofano | F10: Comercial, ventas y cobranzas | G10: JEFE/A | H10: Evaluación técnica | L10: Sobre cápita
B11: SERVICIOS DE ADMINISTRACIÓN | C11: Medical S Org | D11: SUCURSALES-RECEPCION | E11: CABALLITO | F11: Analista IT | G11: ANALISTA | H11: Negociando condiciones | L11: Futura desvinculación
C12: CEMEPRO | D12: TERAPISTAS INTENSIVOS | E12: GUARDIA | F12: Pasante/Becario | G12: INSTRUMENTADOR/A | H12: Carta Oferta
C13: ARGIL SRL | D13: RADIOLOGIA | E13: Imagenes | F13: Liderazgo | G13: ADMIN.OPER.DE RECEPCION | H13: Ingreso
C14: GENESEN SA | D14: Comercial | E14: CONSULTORIOS EXTERNOS | G14: SUPERVISOR/A | H14: StandBy
C15: Farmacia Nobel SA | D15: Atencion al socio | E15: Atencion al socio | G15: COORDINADOR/A | H15: Cancelada
C16: Programa de Salud SA | D16: SUCURSALES-RECEPCION PILAR | E16: FACTURACION Y COBRANZAS | G16: RECEPCIONISTA | H16: Relevamiento de Perfil
C17: Traumato SA | D17: Mantenimiento | E17: Marketing | G17: AYUDANTE | H17: Pendiente de Aprobación
C18: Medin SA | D18: LABORATORIO | E18: Servicio de Apoyo | G18: OFICIAL
C19: Centrol Médico de la Mujer SA | D19: CARDIOLOGIA | E19: Gerencia Medica | G19: OPERARIO/A
C20: Laboratorio Internacional SA | D20: GESTION DE PERSONAS | E20: UNIDAD CORONARIA | G20: BECARIA/O
C21: Centrol Integral de Resonancia SA | D21: TRAUMATOLOGIA | E21: Administración y Finanzas | G21: PEON
D22: Sistemas | E22: FUCOS | G22: RESIDENTE 1*
D23: At. al Paciente | E23: FARMACIA LAMAITE | G23: FACTURISTA
D24: BECARIOS | E24: ARGIL | G24: Cobrador/a
D25: PRESTACIONES MEDICAS | E25: Facturación y Cobranzas | G25: Liquidador/a
D26: ADMINISTRACION Y FINANZAS | E26: DEFAULT | G26: CAMILLERO/A
D27: MEDICA- LABORATORIO | E27: QUILMES | G27: GERENTE/A
D28: SERVICIO DE ALIMENTACION | E28: Default Contable | G28: RESIDENTE 2*
D29: Maestranza | E29: Administracion | G29: ENCARGADO/A
D30: MEDICA CARDIO 2 | E30: Contact Center | G30: RESIDENTE 4*
D31: CAMILLEROS | E31: BMI | G31: RESIDENTE 3*
D32: SUCURSALES-RECEPCION LABORATORIO | E32: Contrataciones | G32: AUXILIAR
D33: Compras | E33: SAN ISIDRO | G33: EMPLEADO/A DE MOSTRADOR
... D48: Performance | E48: Laboratorio | G48: ADMIN.DE COMP. Y EE
D49: DIRECCION GENERAL | G49: ADMISIONISTA
D50: MEDICA RM1 | G50: INSTRUCTOR/A
D51: VENTAS OS.P.P | G51: COCINERO/A
D52: FIDELIZACION Y BAJAS | G52: JEFE/A DE RESIDENTES
D53: Pagos | G53: DIRECTOR/A TECNICO/A
D54: MEDICA RM3 | G54: ANALISTA DE FINANZAS
...

Sheet Estructura del archivo
A1: Identificación de la vacante | B1: Aprobación y confidencialidad | C1: Información organizacional | D1: Información del puesto | E1: Seguimiento del proceso | F1: Tipo de necesidad | G1: Condiciones del puesto | H1: Cierre del proceso | I1: Recursos asignados | J1: Observaciones
A2: N° Vacante | B2: Estado de aprobación | C2: Unidad de Negocio | D2: Familia de Puesto | E2: Status general | F2: Tipo de vacante | G2: Modalidad de contratación | H2: Fecha de cierre | I2: Notebook | J2: Comentarios
A3: Fecha de solicitud | B3: Confidencial | C3: Razón Social | D3: Puesto | E3: Status del proceso | F3: Nombre de reemplazo | G3: Horario | H3: Fecha de ingreso
A4: Días de apertura | B4: Vacante sujeta a futura desvinculación | C4: Sector | D4: Líder | E4: Fecha estimada de ingreso | F4: Motivo de contratación | G4: Lugar de trabajo | H4: Tipo de búsqueda
A5: Selector | B5: Fecha estimada de desvinculación | C5: Centro de Costo | D5: Hiring Manager | E5: Dificultad | G5: CCT | H5: Fuente de selección
E6: Prioridad | H6: Nombre del seleccionado/a
H7: Remuneración acordada
H8: Blue

Sheet Búsqueda rápida. 
A1: Nombre del seleccionado/a: | B1: MAIA ZANE | C1: Seleccionar y/o escribir el nombre del candidato a buscar
A2: Fecha de Ingreso | B2: =_xlfn.XLOOKUP($B$1,BASE!$AJ:$AJ,BASE!$AG:$AG,"No encontrado",0) -> 46146 | C2: Si arroja como resultado "0" y/o "No encontrado" significa que el dato buscado, no se encuentra cargado en la hoja "BASE"
A3: Puesto | B3: =_xlfn.XLOOKUP($B$1,BASE!$AJ:$AJ,BASE!$O:$O,"No encontrado",0) -> TECNICO/A
A4: Sector | B4: =_xlfn.XLOOKUP($B$1,BASE!$AJ:$AJ,BASE!$L:$L,"No encontrado",0) -> LABORATORIO
A5: Centro de Costo | B5: =_xlfn.XLOOKUP($B$1,BASE!$AJ:$AJ,BASE!$M:$M,"No encontrado",0) -> INTERNACION
A6: Remuneración acordada | B6: =_xlfn.XLOOKUP($B$1,BASE!$AJ:$AJ,BASE!$AK:$AK,"No encontrado",0) -> $1.615.215,71 bruto / $1.098.029,50 neto
A7: Horario | B7: =_xlfn.XLOOKUP($B$1,BASE!$AJ:$AJ,BASE!$AD:$AD,"No encontrado",0) -> Lunes a Sábados 14 a 22 hs
A8: CCT | B8: =_xlfn.XLOOKUP($B$1,BASE!$AJ:$AJ,BASE!$AL:$AL,"No encontrado",0) -> 122/75
A9: Modalidad de contratación | B9: =_xlfn.XLOOKUP($B$1,BASE!$AJ:$AJ,BASE!$AA:$AA,"No encontrado",0) -> Inderminado
A10: Lugar de trabajo | B10: =_xlfn.XLOOKUP($B$1,BASE!$AJ:$AJ,BASE!$AE:$AE,"No encontrado",0) -> Sanatorio
A11: Líder | B11: =_xlfn.XLOOKUP($B$1,BASE!$AJ:$AJ,BASE!$P:$P,"No encontrado",0) -> Scarcelli
A12: N° Legajo reemplazo | B12: =_xlfn.XLOOKUP($B$1,BASE!$AJ:$AJ,BASE!$X:$X,"No encontrado",0) -> 0
A13: Nombre reemplazo | B13: =_xlfn.XLOOKUP($B$1,BASE!$AJ:$AJ,BASE!$Y:$Y,"No encontrado",0) -> Violeta Chinski
A14: Selector | B14: =_xlfn.XLOOKUP($B$1,BASE!$AJ:$AJ,BASE!$D:$D,"No encontrado",0) -> Ema
A15: Tipo de vacante | B15: =_xlfn.XLOOKUP($B$1,BASE!$AJ:$AJ,BASE!$W:$W,"No encontrado",0) -> Reemplazo
A16: Sector | B16: =_xlfn.XLOOKUP($B$1,BASE!$AJ:$AJ,BASE!$L:$L,"No encontrado",0) -> LABORATORIO
A17: CC. | B17: =_xlfn.XLOOKUP($B$1,BASE!$AJ:$AJ,BASE!$M:$M,"No encontrado",0) -> INTERNACION
